Workbook

Sheet GANTT
A1: PLAN DE MANTENIMIENTO MAYOR - TRACTOR CAT D8T / CODIGO 05-68
A2: Mina Volcan | Diagrama de Gantt y programacion de frentes en paralelo
A4: Fecha de inicio del proyecto: | C4: 46272
A5: Duracion total del proyecto (dias): | C5: =MAX(F8:F15)-MIN(E8:E15)+1 -> 13
A6: Fecha de entrega a Operaciones: | C6: =$C$4+MAX(F8:F15)-1 -> 46284
A7: ID | B7: ACTIVIDAD | C7: FRENTE / CUADRILLA | D7: DIAS | E7: DIA INI | F7: DIA FIN | G7: FECHA INICIO | H7: FECHA FIN | I7: =$C$4+0 -> 46272 | J7: =$C$4+1 -> 46273 | K7: =$C$4+2 -> 46274 | L7: =$C$4+3 -> 46275 | M7: =$C$4+4 -> 46276 | N7: =$C$4+5 -> 46277 | O7: =$C$4+6 -> 46278 | P7: =$C$4+7 -> 46279 | Q7: =$C$4+8 -> 46280 | R7: =$C$4+9 -> 46281 | S7: =$C$4+10 -> 46282 | T7: =$C$4+11 -> 46283 | U7: =$C$4+12 -> 46284 | V7: =$C$4+13 -> 46285 | W7: =$C$4+14 -> 46286 | X7: =$C$4+15 -> 46287 | Y7: =$C$4+16 -> 46288 | Z7: =$C$4+17 -> 46289
A8: 1 | B8: Reparacion de front idler de los carros | C8: A - Tren de rodaje | D8: 9 | E8: 1 | F8: =E8+D8-1 -> 9 | G8: =$C$4+E8-1 -> 46272 | H8: =$C$4+F8-1 -> 46280
A9: 2 | B9: Cambio de rodos inferiores y superiores | C9: A - Tren de rodaje | D9: 4 | E9: 4 | F9: =E9+D9-1 -> 7 | G9: =$C$4+E9-1 -> 46275 | H9: =$C$4+F9-1 -> 46278
A10: 3 | B10: Reparacion de mando final | C10: A - Tren de rodaje | D10: 2 | E10: 6 | F10: =E10+D10-1 -> 7 | G10: =$C$4+E10-1 -> 46277 | H10: =$C$4+F10-1 -> 46278
A11: 4 | B11: Reconstruccion de hoja topadora (bulldozer) | C11: B - Estructuras y soldadura | D11: 4 | E11: 1 | F11: =E11+D11-1 -> 4 | G11: =$C$4+E11-1 -> 46272 | H11: =$C$4+F11-1 -> 46275
A12: 5 | B12: Cambio de barra ecualizadora | C12: B - Estructuras y soldadura | D12: 2 | E12: 10 | F12: =E12+D12-1 -> 11 | G12: =$C$4+E12-1 -> 46281 | H12: =$C$4+F12-1 -> 46282
A13: 6 | B13: Instalacion de parrilla antiroca | C13: B - Estructuras y soldadura | D13: 2 | E13: 5 | F13: =E13+D13-1 -> 6 | G13: =$C$4+E13-1 -> 46276 | H13: =$C$4+F13-1 -> 46277
A14: 7 | B14: Estandarizacion de sistema de aire acondicionado | C14: C - Climatizacion | D14: 4 | E14: 9 | F14: =E14+D14-1 -> 12 | G14: =$C$4+E14-1 -> 46280 | H14: =$C$4+F14-1 -> 46283
A15: 8 | B15: Montaje de cadenas, tensado y calibracion | C15: A - Tren de rodaje | D15: 1 | E15: 13 | F15: =E15+D15-1 -> 13 | G15: =$C$4+E15-1 -> 46284 | H15: =$C$4+F15-1 -> 46284
B17: LEYENDA
C18: Frente A - Tren de rodaje (mecanicos)
C19: Frente B - Estructuras y soldadura
C20: Frente C - Climatizacion / electrico
C21: Servicio externo - front idler en taller de reconstruccion
C22: Fin de semana
B25: SECUENCIA Y JUSTIFICACION DE PARALELISMOS
B26: 1. Reparacion de front idler de los carros | D26: RUTA CRITICA. Ambos carros. D1 desmontaje de cadenas y extraccion de front idlers / D2 envio a taller de reconstruccion (relleno y maquinado de pistas) / D7 retorno / D8 montaje con sellos y bujes nuevos.
B27: 2. Cambio de rodos inferiores y superiores | D27: En paralelo: se ejecuta con las cadenas ya desmontadas y los front idlers fuera de maquina.
B28: 3. Reparacion de mando final | D28: RIESGO ALTO: 9 partes en EN SOLICITUD DE COMPRA
B29: 4. Reconstruccion de hoja topadora (bulldozer) | D29: Hoja desmontada desde D1; libera el frente para ecualizadora. Consumibles de soldadura, no requiere backlog.
B30: 5. Cambio de barra ecualizadora | D30: En paralelo. Requiere la hoja topadora fuera de maquina (ya desmontada en actividad 4).
B31: 6. Instalacion de parrilla antiroca | D31: Ultimo trabajo con soldadura: se ejecuta ANTES del A/C para no danar mangueras ni condensador nuevos.
B32: 7. Estandarizacion de sistema de aire acondicionado | D32: Inicia con toda la soldadura terminada. Incluye vacio, carga de refrigerante y prueba de estanqueidad.
B33: 8. Montaje de cadenas, tensado y calibracion | D33: Actividad de cierre agregada por planificacion (no estaba en el listado original).
B34: 9. Pruebas funcionales en vacio y con carga | D34: Prueba de 2 h con operador; verificacion de fugas, temperaturas y presiones.

Sheet RESUMEN_REPUESTOS
A1: RESUMEN DE REPUESTOS DEL BACKLOG POR ACTIVIDAD - D8T 05-68
A2: Fuente: REPUESTOS_DE_BACKLOG_05-68.xlsx (archivo entregado por el usuario). El MONTO USD del archivo se toma como monto total de la linea.
A4: ACTIVIDAD | B4: ITEMS | C4: DISPONIBLES | D4: PARCIALES | E4: SIN EXISTENCIA | F4: MONTO USD | G4: % DEL TOTAL | H4: SEMAFORO | I4: Observacion
A5: Reparacion de front idler (rueda guia) de los carros | B5: =COUNTIFS(BACKLOG!$A:$A,$A5) -> 0 | C5: =COUNTIFS(BACKLOG!$A:$A,$A5,BACKLOG!$I:$I,"DISPONIBLE") -> 0 | D5: =COUNTIFS(BACKLOG!$A:$A,$A5,BACKLOG!$I:$I,"PARCIAL") -> 0 | E5: =COUNTIFS(BACKLOG!$A:$A,$A5,BACKLOG!$I:$I,"SIN EXISTENCIA") -> 0 | F5: =SUMIFS(BACKLOG!$L:$L,BACKLOG!$A:$A,$A5) -> 0 | G5: =IFERROR(F5/$F$13,0) -> 0 | H5: =IF(E5>0,"BLOQUEADO",IF(D5>0,"REVISAR","LISTO")) -> LISTO
A6: Cambio de rodos inferiores y superiores | B6: =COUNTIFS(BACKLOG!$A:$A,$A6) -> 11 | C6: =COUNTIFS(BACKLOG!$A:$A,$A6,BACKLOG!$I:$I,"DISPONIBLE") -> 10 | D6: =COUNTIFS(BACKLOG!$A:$A,$A6,BACKLOG!$I:$I,"PARCIAL") -> 1 | E6: =COUNTIFS(BACKLOG!$A:$A,$A6,BACKLOG!$I:$I,"SIN EXISTENCIA") -> 0 | F6: =SUMIFS(BACKLOG!$L:$L,BACKLOG!$A:$A,$A6) -> 15109.911 | G6: =IFERROR(F6/$F$13,0) -> 0.33873354 | H6: =IF(E6>0,"BLOQUEADO",IF(D6>0,"REVISAR","LISTO")) -> REVISAR | I6: Pendiente ingreso de pernos de rodos ingresan: 9/9/26
A7: Reparacion de mando final | B7: =COUNTIFS(BACKLOG!$A:$A,$A7) -> 31 | C7: =COUNTIFS(BACKLOG!$A:$A,$A7,BACKLOG!$I:$I,"DISPONIBLE") -> 21 | D7: =COUNTIFS(BACKLOG!$A:$A,$A7,BACKLOG!$I:$I,"PARCIAL") -> 0 | E7: =COUNTIFS(BACKLOG!$A:$A,$A7,BACKLOG!$I:$I,"SIN EXISTENCIA") -> 10 | F7: =SUMIFS(BACKLOG!$L:$L,BACKLOG!$A:$A,$A7) -> 12972.208 | G7: =IFERROR(F7/$F$13,0) -> 0.29081057 | H7: =IF(E7>0,"BLOQUEADO",IF(D7>0,"REVISAR","LISTO")) -> BLOQUEADO | I7: En Oc, ingresan el 8/9/26
A8: Cambio de barra ecualizadora | B8: =COUNTIFS(BACKLOG!$A:$A,$A8) -> 15 | C8: =COUNTIFS(BACKLOG!$A:$A,$A8,BACKLOG!$I:$I,"DISPONIBLE") -> 15 | D8: =COUNTIFS(BACKLOG!$A:$A,$A8,BACKLOG!$I:$I,"PARCIAL") -> 0 | E8: =COUNTIFS(BACKLOG!$A:$A,$A8,BACKLOG!$I:$I,"SIN EXISTENCIA") -> 0 | F8: =SUMIFS(BACKLOG!$L:$L,BACKLOG!$A:$A,$A8) -> 4700.9901 | G8: =IFERROR(F8/$F$13,0) -> 0.10538666 | H8: =IF(E8>0,"BLOQUEADO",IF(D8>0,"REVISAR","LISTO")) -> LISTO
A9: Instalacion de parrilla antiroca | B9: =COUNTIFS(BACKLOG!$A:$A,$A9) -> 4 | C9: =COUNTIFS(BACKLOG!$A:$A,$A9,BACKLOG!$I:$I,"DISPONIBLE") -> 4 | D9: =COUNTIFS(BACKLOG!$A:$A,$A9,BACKLOG!$I:$I,"PARCIAL") -> 0 | E9: =COUNTIFS(BACKLOG!$A:$A,$A9,BACKLOG!$I:$I,"SIN EXISTENCIA") -> 0 | F9: =SUMIFS(BACKLOG!$L:$L,BACKLOG!$A:$A,$A9) -> 0 | G9: =IFERROR(F9/$F$13,0) -> 0 | H9: =IF(E9>0,"BLOQUEADO",IF(D9>0,"REVISAR","LISTO")) -> LISTO
A10: Estandarizacion de sistema de aire acondicionado | B10: =COUNTIFS(BACKLOG!$A:$A,$A10) -> 32 | C10: =COUNTIFS(BACKLOG!$A:$A,$A10,BACKLOG!$I:$I,"DISPONIBLE") -> 32 | D10: =COUNTIFS(BACKLOG!$A:$A,$A10,BACKLOG!$I:$I,"PARCIAL") -> 0 | E10: =COUNTIFS(BACKLOG!$A:$A,$A10,BACKLOG!$I:$I,"SIN EXISTENCIA") -> 0 | F10: =SUMIFS(BACKLOG!$L:$L,BACKLOG!$A:$A,$A10) -> 9229.0946 | G10: =IFERROR(F10/$F$13,0) -> 0.20689757 | H10: =IF(E10>0,"BLOQUEADO",IF(D10>0,"REVISAR","LISTO")) -> LISTO
A11: Cambio de arnes de transmision | B11: =COUNTIFS(BACKLOG!$A:$A,$A11) -> 4 | C11: =COUNTIFS(BACKLOG!$A:$A,$A11,BACKLOG!$I:$I,"DISPONIBLE") -> 4 | D11: =COUNTIFS(BACKLOG!$A:$A,$A11,BACKLOG!$I:$I,"PARCIAL") -> 0 | E11: =COUNTIFS(BACKLOG!$A:$A,$A11,BACKLOG!$I:$I,"SIN EXISTENCIA") -> 0 | F11: =SUMIFS(BACKLOG!$L:$L,BACKLOG!$A:$A,$A11) -> 2594.8671 | G11: =IFERROR(F11/$F$13,0) -> 0.058171654 | H11: =IF(E11>0,"BLOQUEADO",IF(D11>0,"REVISAR","LISTO")) -> LISTO
A12: Instalacion de protector de turbo | B12: =COUNTIFS(BACKLOG!$A:$A,$A12) -> 1 | C12: =COUNTIFS(BACKLOG!$A:$A,$A12,BACKLOG!$I:$I,"DISPONIBLE") -> 1 | D12: =COUNTIFS(BACKLOG!$A:$A,$A12,BACKLOG!$I:$I,"PARCIAL") -> 0 | E12: =COUNTIFS(BACKLOG!$A:$A,$A12,BACKLOG!$I:$I,"SIN EXISTENCIA") -> 0 | F12: =SUMIFS(BACKLOG!$L:$L,BACKLOG!$A:$A,$A12) -> 342.43194 | G12: =IFERROR(F12/$F$13,0) -> 0.0076766292 | H12: =IF(E12>0,"BLOQUEADO",IF(D12>0,"REVISAR","LISTO")) -> LISTO
A13: TOTAL BACKLOG | B13: =SUM(B5:B11) -> 97 | C13: =SUM(C5:C11) -> 86 | D13: =SUM(D5:D11) -> 1 | E13: =SUM(E5:E11) -> 10 | F13: =SUM(F5:F11) -> 44607.07 | G13: =IFERROR(F13/$F$13,0) -> 1

Sheet BACKLOG
A1: ACTIVIDAD | B1: SISTEMA | C1: CODIGO | D1: # PARTE | E1: DESCRIPCION | F1: CANT. REQ. | G1: EXISTENCIA (texto) | H1: EXIST. TOTAL | I1: ESTADO | J1: UBICACION | K1: ALMACEN | L1: MONTO USD
A2: Reparacion de front idler de los carros | B2: Grupo De Bastidor De Retroceso Longitudinal | C2: 10784 | D2: 3T5898 | E2: RING-RETAINING, 3T5898 | F2: 2 | G2: 4 | 2 | H2: 6 | I2: DISPONIBLE | J2: C2-H04 | BF14J01 | K2: ALMACEN13A | CONSIGNADO NIMAC | L2: 125.48663
A3: Reparacion de front idler de los carros | B3: Grupo De Bastidor De Retroceso Longitudinal | C3: 33882 | D3: 7G7379 | E3: BUJE 7G7379 | F3: 2 | G3: 3 | 2 | H3: 5 | I3: DISPONIBLE | J3: C4-D03 | BE13B02 | K3: ALMACEN13A | CONSIGNADO NIMAC | L3: 177.42755
A4: Reparacion de front idler de los carros | B4: Grupo De Bastidor De Retroceso Longitudinal | C4: 15596 | D4: 9W3301 | E4: RING-RETAINING, 9W3301 | F4: 2 | G4: 3 | 2 | H4: 5 | I4: DISPONIBLE | J4: C2-H04 | C1-2B5 | K4: ALMACEN13A | CONSIGNADO NIMAC | L4: 54.831355
A5: Reparacion de front idler de los carros | B5: Grupo De Bastidor De Retroceso Longitudinal | C5: 33883 | D5: 9X4584 | E5: SEAL AS, 9X4584 | F5: 2 | G5: 4 | 2 | H5: 6 | I5: DISPONIBLE | J5: C2-H01 | BF14J01 | K5: ALMACEN13A | CONSIGNADO NIMAC | L5: 456.90757
A6: Cambio de rodos inferiores y superiores | B6: BASE DE RODO SUPERIOR | C6: 29427 | D6: 1311651 | E6: CAP AS-TRACK ROLLER, 1311651 | F6: 4 | G6: 6 | 40 | H6: 46 | I6: DISPONIBLE | J6: C1-H07 | BF14H01 | K6: ALMACEN13A | CONSIGNADO NIMAC | L6: 153.04374
A7: Cambio de rodos inferiores y superiores | B7: BASE DE RODO SUPERIOR | C7: 51052 | D7: 2873293 | E7: SUPPORT, 2873293 | F7: 4 | G7: 4 | H7: 4 | I7: DISPONIBLE | J7: C1-E01 | K7: ALMACEN13A | L7: 2078.6702
A8: Cambio de rodos inferiores y superiores | B8: BASE DE RODO SUPERIOR | C8: 11609 | D8: 5P8249 | E8: Arandela # 5P-8249 | F8: 8 | G8: 88 | 67 | H8: 155 | I8: DISPONIBLE | J8: C2-B03 | C1-2A2 | K8: ALMACEN13A | CONSIGNADO NIMAC | L8: 21.026477
A9: Cambio de rodos inferiores y superiores | B9: BASE DE RODO SUPERIOR | C9: 13801 | D9: 6T1140 | E9: BOLT-ROLLER MOUNTING, 6T1140 | F9: 8 | G9: 16 | 72 | H9: 88 | I9: DISPONIBLE | J9: C1-F01 | BF14G02 | K9: ALMACEN13A | CONSIGNADO NIMAC | L9: 45.11977
A10: Cambio de rodos inferiores y superiores | B10: BASE DE RODO SUPERIOR | C10: 33683 | D10: 7X0408 | E10: BOLT, 7X0408 | F10: 8 | G10: 8 | H10: 8 | I10: DISPONIBLE | J10: C1-F02 | K10: ALMACEN13A | L10: 135.16709
A11: Cambio de rodos inferiores y superiores | B11: BASE DE RODO SUPERIOR | C11: 33684 | D11: 8T5361 | E11: WASHER-HARD, 8T5361 | F11: 8 | G11: 10 | H11: 10 | I11: DISPONIBLE | J11: C3-G03 | K11: ALMACEN13A | L11: 35.521771
A12: Cambio de rodos inferiores y superiores | B12: Rodos | C12: 29427 | D12: 1311651 | E12: CAP AS-TRACK ROLLER, 1311651 | F12: 36 | G12: 6 | 40 | H12: 46 | I12: DISPONIBLE | J12: C1-H07 | BF14H01 | K12: ALMACEN13A | CONSIGNADO NIMAC | L12: 1377.3937
A13: Cambio de rodos inferiores y superiores | B13: Rodos | C13: 78659 | D13: 4197172 | E13: ROLLER GP-TRACK SINGLE, 4197172 | F13: 1 | G13: 1 | H13: 1 | I13: DISPONIBLE | J13: 33A01 | K13: ALMACEN13A | L13: 603.14682
A14: Cambio de rodos inferiores y superiores | B14: Rodos | C14: 95529 | D14: 6156356 | E14: RODO | F14: 9 | G14: 9 | H14: 9 | I14: DISPONIBLE | J14: 0 | K14: CONSIGNADO NIMAC | L14: 5713.5574
A15: Cambio de rodos inferiores y superiores | B15: Rodos | C15: 95530 | D15: 6156360 | E15: RODO | F15: 8 | G15: 8 | H15: 8 | I15: DISPONIBLE | J15: 0 | K15: CONSIGNADO NIMAC | L15: 4947.264
A16: Cambio de rodos inferiores y superiores | B16: Rodos | C16: 754 | D16: 6C3220 | E16: BOLT | F16: 64 | G16: 20 | H16: 20 | I16: PARCIAL | J16: B11A01 | K16: CONSIGNADO NIMAC | L16: 0
A17: Reparacion de mando final | B17: MANDO FINAL | C17: 35053 | D17: 1M7911 | E17: Cuna | F17: 8 | G17: 8 | H17: 8 | I17: DISPONIBLE | J17: C2-H03 | K17: ALMACEN13A | L17: 352.77125
A18: Reparacion de mando final | B18: MANDO FINAL | C18: Sin Existencia | D18: 1M7912 | E18: Sin Existencia | F18: 8 | G18: Sin Existencia | H18: 0 | I18: SIN EXISTENCIA | J18: Sin Existencia | Sin Existencia | K18: Sin Existencia | Sin Existencia | L18: 0
A19: Reparacion de mando final | B19: MANDO FINAL | C19: 25312 | D19: 2R0098 | E19: SEAL-O-RING, 2R0098 | F19: 1 | G19: 1 | 1 | H19: 2 | I19: DISPONIBLE | J19: C1-C02 | C5-J01 | K19: ALMACEN01H | ALMACEN13A | L19: 23.276349
A20: Reparacion de mando final | B20: MANDO FINAL | C20: 9874 | D20: 2S4078 | E20: Sello 2S4078 | F20: 1 | G20: 6 | 2 | H20: 8 | I20: DISPONIBLE | J20: C1-C02 | BF20C03 | K20: ALMACEN13A | CONSIGNADO NIMAC | L20: 0.87346379
A21: Reparacion de mando final | B21: MANDO FINAL | C21: 46786 | D21: 3909923 | E21: Carcasa | F21: 1 | G21: 1 | H21: 1 | I21: DISPONIBLE | J21: 30A01 | K21: ALMACEN01H | L21: 8541.8782
A22: Reparacion de mando final | B22: MANDO FINAL | C22: Sin Existencia | D22: 3D2895 | E22: Sin Existencia | F22: 4 | G22: Sin Existencia | H22: 0 | I22: SIN EXISTENCIA | J22: Sin Existencia | Sin Existencia | K22: Sin Existencia | Sin Existencia | L22: 0
A23: Reparacion de mando final | B23: MANDO FINAL | C23: 10709 | D23: 3K0360 | E23: Sello (Caucho)/3K0360 | F23: 1 | G23: 1 | 4 | H23: 5 | I23: DISPONIBLE | J23: C2-D03 | BF14D03 | K23: ALMACEN01H | CONSIGNADO NIMAC | L23: 1.8315708
A24: Reparacion de mando final | B24: MANDO FINAL | C24: Sin Existencia | D24: 3T5923 | E24: Sin Existencia | F24: 1 | G24: Sin Existencia | H24: 0 | I24: SIN EXISTENCIA | J24: Sin Existencia | Sin Existencia | K24: Sin Existencia | Sin Existencia | L24: 0
A25: Reparacion de mando final | B25: MANDO FINAL | C25: 23163 | D25: 5F2465 | E25: Cuna para Balinera | F25: 1 | G25: 1 | H25: 1 | I25: DISPONIBLE | J25: C6-E03 | K25: ALMACEN13A | L25: 58.085479
A26: Reparacion de mando final | B26: MANDO FINAL | C26: 32814 | D26: 5F7054 | E26: SEAL-O-RING, 5F7054 | F26: 1 | G26: 1 | 1 | H26: 2 | I26: DISPONIBLE | J26: C2-I03 | BF12C02 | K26: ALMACEN13A | CONSIGNADO NIMAC | L26: 0.59059149
A27: Reparacion de mando final | B27: MANDO FINAL | C27: 87013 | D27: 5K8454 | E27: BOLT, 5K8454 | F27: 15 | G27: 21 | H27: 21 | I27: DISPONIBLE | J27: C2-F03 | K27: ALMACEN13A | L27: 26.851025
A28: Reparacion de mando final | B28: MANDO FINAL | C28: 35048 | D28: 5P8472 | E28: RING-RETAINING, 5P8472 | F28: 1 | G28: 1 | H28: 1 | I28: DISPONIBLE | J28: C4-J01 | K28: ALMACEN13A | L28: 0.027304276
A29: Reparacion de mando final | B29: MANDO FINAL | C29: 46787 | D29: 6T2173 | E29: PIN, 6T2173 | F29: 15 | G29: 15 | H29: 15 | I29: DISPONIBLE | J29: C3-A02 | K29: ALMACEN13A | L29: 144.79731
A30: Reparacion de mando final | B30: MANDO FINAL | C30: Sin Existencia | D30: 6V0662 | E30: Sin Existencia | F30: 1 | G30: Sin Existencia | H30: 0 | I30: SIN EXISTENCIA | J30: Sin Existencia | Sin Existencia | K30: Sin Existencia | Sin Existencia | L30: 0
A31: Reparacion de mando final | B31: MANDO FINAL | C31: Sin Existencia | D31: 6V0663 | E31: Sin Existencia | F31: 1 | G31: Sin Existencia | H31: 0 | I31: SIN EXISTENCIA | J31: Sin Existencia | Sin Existencia | K31: Sin Existencia | Sin Existencia | L31: 0
A32: Reparacion de mando final | B32: MANDO FINAL | C32: 35039 | D32: 6V0664 | E32: BEARING, CONE 6V-0664 | F32: 1 | G32: 1 | H32: 1 | I32: DISPONIBLE | J32: C6-D02 | K32: ALMACEN13A | L32: 0.027304276
A33: Reparacion de mando final | B33: MANDO FINAL | C33: 35040 | D33: 6Y0859 | E33: SEAL GP-DUO-CONE, 6Y-0859 | F33: 1 | G33: 1 | 2 | H33: 3 | I33: DISPONIBLE | J33: C1-C02 | C3-C02 | K33: ALMACEN01H | ALMACEN13A | L33: 148.2259
A34: Reparacion de mando final | B34: MANDO FINAL | C34: 25400 | D34: 7G5831 | E34: RING, 7G5831 | F34: 1 | G34: 1 | H34: 1 | I34: DISPONIBLE | J34: C6-C05 | K34: ALMACEN13A | L34: 0.027304276
A35: Reparacion de mando final | B35: MANDO FINAL | C35: 46784 | D35: 7G5832 | E35: Retenedor | F35: 1 | G35: 1 | H35: 1 | I35: DISPONIBLE | J35: C2-H03 | K35: ALMACEN13A | L35: 882.31557
A36: Reparacion de mando final | B36: MANDO FINAL | C36: Sin Existencia | D36: 7T2524 | E36: Sin Existencia | F36: 1 | G36: Sin Existencia | H36: 0 | I36: SIN EXISTENCIA | J36: Sin Existencia | Sin Existencia | K36: Sin Existencia | Sin Existencia | L36: 0
A37: Reparacion de mando final | B37: MANDO FINAL | C37: 35041 | D37: 7T2530 | E37: ANILLO | F37: 2 | G37: 0 | H37: 0 | I37: SIN EXISTENCIA | J37: CONTENEDOR 3 | K37: CONSIGNADO NIMAC | L37: 0
A38: Reparacion de mando final | B38: MANDO FINAL | C38: 35042 | D38: 7T9526 | E38: Cono | F38: 8 | G38: 16 | H38: 16 | I38: DISPONIBLE | J38: C2-H03 | K38: ALMACEN13A | L38: 835.59385
A39: Reparacion de mando final | B39: MANDO FINAL | C39: 35043 | D39: 7T9527 | E39: Pista | F39: 8 | G39: 8 | H39: 8 | I39: DISPONIBLE | J39: C2-H03 | K39: ALMACEN13A | L39: 545.53507
A40: Reparacion de mando final | B40: MANDO FINAL | C40: 24741 | D40: 7X4777 | E40: SEAL-LIP TYPE, 7X4777 | F40: 1 | G40: 1 | H40: 1 | I40: DISPONIBLE | J40: C2-H03 | K40: ALMACEN13A | L40: 61.175777
...
